Workbook

Sheet план продаж
A1: Группа | B1: общая загрузка, шт | C1: № заказа | D1: Вид продукции | E1: вес 1 шт, кг | F1: ед. изм. | G1: ПЛАН | H1: ФАКТ | I1: %выполнения | J1: Примечание
A2: Мешки | B2: =G2+G4 -> 1504621.1 | C2: 1 | D2: МП-I-ArB с лог "EAC" 56*96 (76 гр\м2) | E2: 0.11 | F2: шт | G2: 1000000 | I2: =H2*100/G2 -> 0 | J2: сахар
F3: кг | G3: =G2*E2 -> 110000 | I3: =H3*100/G3 -> 0
C4: 2 | D4: МП-I-A с лог 56*105 (63 гр\м2) | E4: =0.56*1.08*2*0.063+0.003 -> 0.0792048 | F4: шт | G4: ='черновик с расчетами'!G4 -> 504621.06 | I4: =H4*100/G4 -> 0 | J4: мука
F5: кг | G5: =G4*E4 -> 39968.41 | I5: =H5*100/G5 -> 0
A6: МКР 4 ленточные | B6: =G6+G8+G10+G12+G14+G16+G18+G20+G22+G24 -> 65000 | C6: 3 | D6: МКР 1,3 Л4-1,0 ППР1-Е (95х95х130/140) верх открытый, дно глухое | E6: 1.272 | F6: шт | G6: 5000 | I6: =H6*100/G6 -> 0 | J6: МКР 95х95х130х140
F7: кг | G7: =G6*E6 -> 6360 | I7: =H7*100/G7 -> 0
C8: 4 | D8: МКР 1,3 Л4-1,0 ППР1-Е (95х95х130/140) верх юбка, дно глухое | E8: 1.51 | F8: шт | G8: 20000 | I8: =H8*100/G8 -> 0 | J8: МКР 95х95х130х140
F9: кг | G9: =G8*E8 -> 30200 | I9: =H9*100/G9 -> 0
C10: 5 | D10: МКР 1,3 Л4-1,0 ППР1-Е (95х95х130/140) верх загр, низ выгр | E10: 1.605 | F10: шт | G10: 5000 | I10: =H10*100/G10 -> 0 | J10: МКР 95х95х130х140
F11: кг | G11: =G10*E10 -> 8025 | I11: =H11*100/G11 -> 0
C12: 6 | D12: МКР 1,3 Л4-1,0 ППР1-Е (95х95х150/140) верх открытый, дно глухое | E12: 1.401 | F12: шт | G12: 3000 | I12: =H12*100/G12 -> 0 | J12: МКР 95х95х150х140
F13: кг | G13: =G12*E12 -> 4203 | I13: =H13*100/G13 -> 0
C14: 7 | D14: МКР 1,3 Л4-1,0 ППР1-Е (95х95х150/140) верх юбка, дно глухое | E14: 1.64 | F14: шт | G14: 7000 | I14: =H14*100/G14 -> 0 | J14: МКР 95х95х150х140
F15: кг | G15: =G14*E14 -> 11480 | I15: =H15*100/G15 -> 0
C16: 8 | D16: МКР 1,3 Л4-1,0 ППР1-Е (95х95х150/140) верх загр, дно глухое | E16: 1.661 | F16: шт | G16: 5000 | I16: =H16*100/G16 -> 0 | J16: МКР 95х95х150х140
F17: кг | G17: =G16*E16 -> 8305 | I17: =H17*100/G17 -> 0
C18: 9 | D18: МКР 1,3 Л4-1,0 ППР1-Е (95х95х180/140) верх загр, низ выгре | E18: 1.941 | F18: шт | G18: 5000 | I18: =H18*100/G18 -> 0 | J18: МКР 95х95х180х140
F19: кг | G19: =G18*E18 -> 9705 | I19: =H19*100/G19 -> 0
C20: 10 | D20: МКР 1,3 Л4-1,0 ППР1-Е (95х95х130/140) верх загр, дно глухое | E20: 1.532 | F20: шт | G20: 5000 | I20: =H20*100/G20 -> 0 | J20: МКР 95х95х130х140
F21: кг | G21: =G20*E20 -> 7660 | I21: =H21*100/G21 -> 0
C22: 11 | D22: МКР 1,3 Л4-1,0 ППР1-Е (95х95х130/160) верх юбка, дно глухое | E22: 1.615 | F22: шт | G22: 5000 | I22: =H22*100/G22 -> 0 | J22: МКР 95х95х130х160
F23: кг | G23: =G22*E22 -> 8075 | I23: =H23*100/G23 -> 0
C24: 12 | D24: МКР 1,3 Л4-1,0 ППР1-Е (95х95х130/160) верх загр, низ выгр | E24: 1.71 | F24: шт | G24: 5000 | I24: =H24*100/G24 -> 0 | J24: МКР 95х95х130х160
F25: кг | G25: =G24*E24 -> 8550 | I25: =H25*100/G25 -> 0
A26: МКР 2х стропные | B26: =G26+G28 -> 45000 | C26: 13 | D26: МКР 0,9 С2-1,0 ППР1-A (75х75х125/120) верх открытый, дно звезда | E26: =0.776 -> 0.776 | F26: шт | G26: 40000 | I26: =H26*100/G26 -> 0 | J26: МКР 75х75х125х120
F27: кг | G27: =G26*E26 -> 31040 | I27: =H27*100/G27 -> 0
C28: 14 | D28: МКР 0,9 С2-1,0 ППР1-A (75х75х125/140) верх открытый, дно звезда | E28: 0.899 | F28: шт | G28: 5000 | I28: =H28*100/G28 -> 0 | J28: МКР 75х75х125х140
F29: кг | G29: =G28*E28 -> 4495 | I29: =H29*100/G29 -> 0

Sheet план производства 
A1: № п\п | B1: Участок | C1: Наименование | D1: Дата\сутки | G1: 45809 | J1: 45810 | M1: 45811 | P1: 45812 | S1: 45813 | V1: 45814 | Y1: 45815 | AB1: 45816 | AE1: 45817 | AH1: 45818 | AK1: 45819 | AN1: 45820 | AQ1: 45821 | AT1: 45822 | AW1: 45823 | AZ1: 45824 | BC1: 45825 | BF1: 45826 | BI1: 45827 | BL1: 45828 | BO1: 45829 | BR1: 45830 | BU1: 45831 | BX1: 45832 | CA1: 45833 | CD1: 45834 | CG1: 45835 | CJ1: 45836 | CM1: 45837 | CP1: 45838
D2: План на месяц | E2: Факт за месяц | F2: % выполнения от месячного плана | G2: План на сутки | H2: Факт за сутки | I2: Причины не выполнения | J2: План на сутки | K2: Факт за сутки | L2: Причины не выполнения | M2: План на сутки | N2: Факт за сутки | O2: Причины не выполнения | P2: План на сутки | Q2: Факт за сутки | R2: Причины не выполнения | S2: План на сутки | T2: Факт за сутки | U2: Причины не выполнения | V2: План на сутки | W2: Факт за сутки | X2: Причины не выполнения | Y2: План на сутки | Z2: Факт за сутки | AA2: Причины не выполнения | AB2: План на сутки | AC2: Факт за сутки | AD2: Причины не выполнения | AE2: План на сутки | AF2: Факт за сутки | AG2: Причины не выполнения | AH2: План на сутки | AI2: Факт за сутки | AJ2: Причины не выполнения | AK2: План на сутки | AL2: Факт за сутки | AM2: Причины не выполнения | AN2: План на сутки | AO2: Факт за сутки | AP2: Причины не выполнения | AQ2: План на сутки | AR2: Факт за сутки | AS2: Причины не выполнения | AT2: План на сутки | AU2: Факт за сутки | AV2: Причины не выполнения | AW2: План на сутки | AX2: Факт за сутки | AY2: Причины не выполнения | AZ2: План на сутки | BA2: Факт за сутки | BB2: Причины не выполнения | BC2: План на сутки | BD2: Факт за сутки | BE2: Причины не выполнения | BF2: План на сутки | BG2: Факт за сутки | BH2: Причины не выполнения | BI2: План на сутки | BJ2: Факт за сутки | BK2: Причины не выполнения | BL2: План на сутки | BM2: Факт за сутки | BN2: Причины не выполнения | BO2: План на сутки | BP2: Факт за сутки | BQ2: Причины не выполнения | BR2: План на сутки | BS2: Факт за сутки | BT2: Причины не выполнения | BU2: План на сутки | BV2: Факт за сутки | BW2: Причины не выполнения | BX2: План на сутки | BY2: Факт за сутки | BZ2: Причины не выполнения | CA2: План на сутки | CB2: Факт за сутки | CC2: Причины не выполнения | CD2: План на сутки | CE2: Факт за сутки | CF2: Причины не выполнения | CG2: План на сутки | CH2: Факт за сутки | CI2: Причины не выполнения | CJ2: План на сутки | CK2: Факт за сутки | CL2: Причины не выполнения | CM2: План на сутки | CN2: Факт за сутки | CO2: Причины не выполнения | CP2: План на сутки | CQ2: Факт за сутки | CR2: Причины не выполнения
A3: 1 | B3: Экструдер, кг | C3: Нить мешки | D3: ='экструдер '!G13 -> 149090 | E3: =AU3+AX3+BA3+BD3+BG3+BJ3+AR3+AO3+AL3+AI3+H3+N3+Q3+T3+W3+Z3+AC3+AF3+K3+BM3+BP3+BS3+BV3+BY3+CB3+CE3+CH3+CN3+CK3+CQ3 -> 0 | F3: =E3*100/D3 -> 0 | G3: =D3/30 -> 4969.6667 | J3: =D3/30 -> 4969.6667 | M3: =G3 -> 4969.6667 | P3: =J3 -> 4969.6667 | S3: =M3 -> 4969.6667 | V3: =P3 -> 4969.6667 | Y3: =S3 -> 4969.6667 | AB3: =V3 -> 4969.6667 | AE3: =Y3 -> 4969.6667 | AH3: =AB3 -> 4969.6667 | AK3: =AE3 -> 4969.6667 | AN3: =AH3 -> 4969.6667 | AQ3: =AK3 -> 4969.6667 | AT3: =AN3 -> 4969.6667 | AW3: =AQ3 -> 4969.6667 | AZ3: =AT3 -> 4969.6667 | BC3: =AW3 -> 4969.6667 | BF3: =AZ3 -> 4969.6667 | BI3: =BC3 -> 4969.6667 | BL3: =BF3 -> 4969.6667 | BO3: =BI3 -> 4969.6667 | BR3: =BL3 -> 4969.6667 | BU3: =BO3 -> 4969.6667 | BX3: =BR3 -> 4969.6667 | CA3: =BU3 -> 4969.6667 | CD3: =BX3 -> 4969.6667 | CG3: =CA3 -> 4969.6667 | CJ3: =CD3 -> 4969.6667 | CM3: =CG3 -> 4969.6667 | CP3: =CJ3 -> 4969.6667
C4: Нить ББ | D4: ='экструдер '!G24 -> 105479 | E4: =AU4+AX4+BA4+BD4+BG4+BJ4+AR4+AO4+AL4+AI4+H4+N4+Q4+T4+W4+Z4+AC4+AF4+K4+BM4+BP4+BS4+BV4+BY4+CB4+CE4+CH4+CN4+CK4+CQ4 -> 0 | F4: =E4*100/D4 -> 0 | G4: =D4/30 -> 3515.9667 | J4: =D4/30 -> 3515.9667 | M4: =G4 -> 3515.9667 | P4: =J4 -> 3515.9667 | S4: =M4 -> 3515.9667 | V4: =P4 -> 3515.9667 | Y4: =S4 -> 3515.9667 | AB4: =V4 -> 3515.9667 | AE4: =Y4 -> 3515.9667 | AH4: =AB4 -> 3515.9667 | AK4: =AE4 -> 3515.9667 | AN4: =AH4 -> 3515.9667 | AQ4: =AK4 -> 3515.9667 | AT4: =AN4 -> 3515.9667 | AW4: =AQ4 -> 3515.9667 | AZ4: =AT4 -> 3515.9667 | BC4: =AW4 -> 3515.9667 | BF4: =AZ4 -> 3515.9667 | BI4: =BC4 -> 3515.9667 | BL4: =BF4 -> 3515.9667 | BO4: =BI4 -> 3515.9667 | BR4: =BL4 -> 3515.9667 | BU4: =BO4 -> 3515.9667 | BX4: =BR4 -> 3515.9667 | CA4: =BU4 -> 3515.9667 | CD4: =BX4 -> 3515.9667 | CG4: =CA4 -> 3515.9667 | CJ4: =CD4 -> 3515.9667 | CM4: =CG4 -> 3515.9667 | CP4: =CJ4 -> 3515.9667
A5: 2 | B5: ткацкий, м | C5: мешочное полотно | D5: ='план ткацкий просте станки'!N7 -> 1782000 | E5: =AU5+AX5+BA5+BD5+BG5+BJ5+AR5+AO5+AL5+AI5+H5+N5+Q5+T5+W5+Z5+AC5+AF5+K5+BM5+BP5+BS5+BV5+BY5+CB5+CE5+CH5+CN5+CK5+CQ5 -> 0 | F5: =E5*100/D5 -> 0 | G5: =D5/30 -> 59400 | J5: =D5/30 -> 59400 | M5: =G5 -> 59400 | P5: =J5 -> 59400 | S5: =M5 -> 59400 | V5: =P5 -> 59400 | Y5: =S5 -> 59400 | AB5: =V5 -> 59400 | AE5: =Y5 -> 59400 | AH5: =AB5 -> 59400 | AK5: =AE5 -> 59400 | AN5: =AH5 -> 59400 | AQ5: =AK5 -> 59400 | AT5: =AN5 -> 59400 | AW5: =AQ5 -> 59400 | AZ5: =AT5 -> 59400 | BC5: =AW5 -> 59400 | BF5: =AZ5 -> 59400 | BI5: =BC5 -> 59400 | BL5: =BF5 -> 59400 | BO5: =BI5 -> 59400 | BR5: =BL5 -> 59400 | BU5: =BO5 -> 59400 | BX5: =BR5 -> 59400 | CA5: =BU5 -> 59400 | CD5: =BX5 -> 59400 | CG5: =CA5 -> 59400 | CJ5: =CD5 -> 59400 | CM5: =CG5 -> 59400 | CP5: =CJ5 -> 59400
C6: МКР полотно | D6: ='план бб'!N10 -> 234727.5 | E6: =AU6+AX6+BA6+BD6+BG6+BJ6+AR6+AO6+AL6+AI6+H6+N6+Q6+T6+W6+Z6+AC6+AF6+K6+BM6+BP6+BS6+BV6+BY6+CB6+CE6+CH6+CN6+CK6+CQ6 -> 0 | F6: =E6*100/D6 -> 0 | G6: =D6/30 -> 7824.25 | J6: =D6/30 -> 7824.25 | M6: =G6 -> 7824.25 | P6: =J6 -> 7824.25 | S6: =M6 -> 7824.25 | V6: =P6 -> 7824.25 | Y6: =S6 -> 7824.25 | AB6: =V6 -> 7824.25 | AE6: =Y6 -> 7824.25 | AH6: =AB6 -> 7824.25 | AK6: =AE6 -> 7824.25 | AN6: =AH6 -> 7824.25 | AQ6: =AK6 -> 7824.25 | AT6: =AN6 -> 7824.25 | AW6: =AQ6 -> 7824.25 | AZ6: =AT6 -> 7824.25 | BC6: =AW6 -> 7824.25 | BF6: =AZ6 -> 7824.25 | BI6: =BC6 -> 7824.25 | BL6: =BF6 -> 7824.25 | BO6: =BI6 -> 7824.25 | BR6: =BL6 -> 7824.25 | BU6: =BO6 -> 7824.25 | BX6: =BR6 -> 7824.25 | CA6: =BU6 -> 7824.25 | CD6: =BX6 -> 7824.25 | CG6: =CA6 -> 7824.25 | CJ6: =CD6 -> 7824.25 | CM6: =CG6 -> 7824.25 | CP6: =CJ6 -> 7824.25
A7: 3 | B7: раскройный , шт | C7: МКР 4 ленточные | D7: ='раскрой бб'!C66-SUM('раскрой бб'!C62:C65) -> 227000 | E7: =AU7+AX7+BA7+BD7+BG7+BJ7+AR7+AO7+AL7+AI7+H7+N7+Q7+T7+W7+Z7+AC7+AF7+K7+BM7+BP7+BS7+BV7+BY7+CB7+CE7+CH7+CN7+CK7+CQ7 -> 0 | F7: =E7*100/D7 -> 0 | G7: =D7/30 -> 7566.6667 | J7: =D7/30 -> 7566.6667 | M7: =G7 -> 7566.6667 | P7: =J7 -> 7566.6667 | S7: =M7 -> 7566.6667 | V7: =P7 -> 7566.6667 | Y7: =S7 -> 7566.6667 | AB7: =V7 -> 7566.6667 | AE7: =Y7 -> 7566.6667 | AH7: =AB7 -> 7566.6667 | AK7: =AE7 -> 7566.6667 | AN7: =AH7 -> 7566.6667 | AQ7: =AK7 -> 7566.6667 | AT7: =AN7 -> 7566.6667 | AW7: =AQ7 -> 7566.6667 | AZ7: =AT7 -> 7566.6667 | BC7: =AW7 -> 7566.6667 | BF7: =AZ7 -> 7566.6667 | BI7: =BC7 -> 7566.6667 | BL7: =BF7 -> 7566.6667 | BO7: =BI7 -> 7566.6667 | BR7: =BL7 -> 7566.6667 | BU7: =BO7 -> 7566.6667 | BX7: =BR7 -> 7566.6667 | CA7: =BU7 -> 7566.6667 | CD7: =BX7 -> 7566.6667 | CG7: =CA7 -> 7566.6667 | CJ7: =CD7 -> 7566.6667 | CM7: =CG7 -> 7566.6667 | CP7: =CJ7 -> 7566.6667
C8: МКР 2х стропыне | D8: ='раскрой бб'!C66-SUM('раскрой бб'!C29:C61) -> 135000 | E8: =AU8+AX8+BA8+BD8+BG8+BJ8+AR8+AO8+AL8+AI8+H8+N8+Q8+T8+W8+Z8+AC8+AF8+K8+BM8+BP8+BS8+BV8+BY8+CB8+CE8+CH8+CN8+CK8+CQ8 -> 0 | F8: =E8*100/D8 -> 0 | G8: =D8/30 -> 4500 | J8: =D8/30 -> 4500 | M8: =G8 -> 4500 | P8: =J8 -> 4500 | S8: =M8 -> 4500 | V8: =P8 -> 4500 | Y8: =S8 -> 4500 | AB8: =V8 -> 4500 | AE8: =Y8 -> 4500 | AH8: =AB8 -> 4500 | AK8: =AE8 -> 4500 | AN8: =AH8 -> 4500 | AQ8: =AK8 -> 4500 | AT8: =AN8 -> 4500 | AW8: =AQ8 -> 4500 | AZ8: =AT8 -> 4500 | BC8: =AW8 -> 4500 | BF8: =AZ8 -> 4500 | BI8: =BC8 -> 4500 | BL8: =BF8 -> 4500 | BO8: =BI8 -> 4500 | BR8: =BL8 -> 4500 | BU8: =BO8 -> 4500 | BX8: =BR8 -> 4500 | CA8: =BU8 -> 4500 | CD8: =BX8 -> 4500 | CG8: =CA8 -> 4500 | CJ8: =CD8 -> 4500 | CM8: =CG8 -> 4500 | CP8: =CJ8 -> 4500
A9: 4 | B9: ТЛБ ЛЕНТА, кг | C9: широкая 4,5 см | D9: ='тлб лента'!J48+('тлб лента'!J48*5/100) -> 21554.883 | E9: =AU9+AX9+BA9+BD9+BG9+BJ9+AR9+AO9+AL9+AI9+H9+N9+Q9+T9+W9+Z9+AC9+AF9+K9+BM9+BP9+BS9+BV9+BY9+CB9+CE9+CH9+CN9+CK9+CQ9 -> 0 | F9: =E9*100/D9 -> 0 | G9: =D9/30 -> 718.4961 | J9: =D9/30 -> 718.4961 | M9: =G9 -> 718.4961 | P9: =J9 -> 718.4961 | S9: =M9 -> 718.4961 | V9: =P9 -> 718.4961 | Y9: =S9 -> 718.4961 | AB9: =V9 -> 718.4961 | AE9: =Y9 -> 718.4961 | AH9: =AB9 -> 718.4961 | AK9: =AE9 -> 718.4961 | AN9: =AH9 -> 718.4961 | AQ9: =AK9 -> 718.4961 | AT9: =AN9 -> 718.4961 | AW9: =AQ9 -> 718.4961 | AZ9: =AT9 -> 718.4961 | BC9: =AW9 -> 718.4961 | BF9: =AZ9 -> 718.4961 | BI9: =BC9 -> 718.4961 | BL9: =BF9 -> 718.4961 | BO9: =BI9 -> 718.4961 | BR9: =BL9 -> 718.4961 | BU9: =BO9 -> 718.4961 | BX9: =BR9 -> 718.4961 | CA9: =BU9 -> 718.4961 | CD9: =BX9 -> 718.4961 | CG9: =CA9 -> 718.4961 | CJ9: =CD9 -> 718.4961 | CM9: =CG9 -> 718.4961 | CP9: =CJ9 -> 718.4961
C10: узкая 1,5см | D10: ='тлб лента'!J49+('тлб лента'!J49*5/100) -> 1882.125 | E10: =AU10+AX10+BA10+BD10+BG10+BJ10+AR10+AO10+AL10+AI10+H10+N10+Q10+T10+W10+Z10+AC10+AF10+K10+BM10+BP10+BS10+BV10+BY10+CB10+CE10+CH10+CN10+CK10+CQ10 -> 0 | F10: =E10*100/D10 -> 0 | G10: =D10/30 -> 62.7375 | J10: =D10/30 -> 62.7375 | M10: =G10 -> 62.7375 | P10: =J10 -> 62.7375 | S10: =M10 -> 62.7375 | V10: =P10 -> 62.7375 | Y10: =S10 -> 62.7375 | AB10: =V10 -> 62.7375 | AE10: =Y10 -> 62.7375 | AH10: =AB10 -> 62.7375 | AK10: =AE10 -> 62.7375 | AN10: =AH10 -> 62.7375 | AQ10: =AK10 -> 62.7375 | AT10: =AN10 -> 62.7375 | AW10: =AQ10 -> 62.7375 | AZ10: =AT10 -> 62.7375 | BC10: =AW10 -> 62.7375 | BF10: =AZ10 -> 62.7375 | BI10: =BC10 -> 62.7375 | BL10: =BF10 -> 62.7375 | BO10: =BI10 -> 62.7375 | BR10: =BL10 -> 62.7375 | BU10: =BO10 -> 62.7375 | BX10: =BR10 -> 62.7375 | CA10: =BU10 -> 62.7375 | CD10: =BX10 -> 62.7375 | CG10: =CA10 -> 62.7375 | CJ10: =CD10 -> 62.7375 | CM10: =CG10 -> 62.7375 | CP10: =CJ10 -> 62.7375
A11: 5 | B11: Швейный МКР | C11: МКР 4 ленточные | D11: 65000 | E11: =AU11+AX11+BA11+BD11+BG11+BJ11+AR11+AO11+AL11+AI11+H11+N11+Q11+T11+W11+Z11+AC11+AF11+K11+BM11+BP11+BS11+BV11+BY11+CB11+CE11+CH11+CN11+CK11+CQ11 -> 0 | F11: =E11*100/D11 -> 0 | G11: =D11/30 -> 2166.6667 | J11: =D11/30 -> 2166.6667 | M11: =G11 -> 2166.6667 | P11: =J11 -> 2166.6667 | S11: =M11 -> 2166.6667 | V11: =P11 -> 2166.6667 | Y11: =S11 -> 2166.6667 | AB11: =V11 -> 2166.6667 | AE11: =Y11 -> 2166.6667 | AH11: =AB11 -> 2166.6667 | AK11: =AE11 -> 2166.6667 | AN11: =AH11 -> 2166.6667 | AQ11: =AK11 -> 2166.6667 | AT11: =AN11 -> 2166.6667 | AW11: =AQ11 -> 2166.6667 | AZ11: =AT11 -> 2166.6667 | BC11: =AW11 -> 2166.6667 | BF11: =AZ11 -> 2166.6667 | BI11: =BC11 -> 2166.6667 | BL11: =BF11 -> 2166.6667 | BO11: =BI11 -> 2166.6667 | BR11: =BL11 -> 2166.6667 | BU11: =BO11 -> 2166.6667 | BX11: =BR11 -> 2166.6667 | CA11: =BU11 -> 2166.6667 | CD11: =BX11 -> 2166.6667 | CG11: =CA11 -> 2166.6667 | CJ11: =CD11 -> 2166.6667 | CM11: =CG11 -> 2166.6667 | CP11: =CJ11 -> 2166.6667
C12: МКР 2х стропыне | D12: =45000 -> 45000 | E12: =AU12+AX12+BA12+BD12+BG12+BJ12+AR12+AO12+AL12+AI12+H12+N12+Q12+T12+W12+Z12+AC12+AF12+K12+BM12+BP12+BS12+BV12+BY12+CB12+CE12+CH12+CN12+CK12+CQ12 -> 0 | F12: =E12*100/D12 -> 0 | G12: =D12/30 -> 1500 | J12: =D12/30 -> 1500 | M12: =G12 -> 1500 | P12: =J12 -> 1500 | S12: =M12 -> 1500 | V12: =P12 -> 1500 | Y12: =S12 -> 1500 | AB12: =V12 -> 1500 | AE12: =Y12 -> 1500 | AH12: =AB12 -> 1500 | AK12: =AE12 -> 1500 | AN12: =AH12 -> 1500 | AQ12: =AK12 -> 1500 | AT12: =AN12 -> 1500 | AW12: =AQ12 -> 1500 | AZ12: =AT12 -> 1500 | BC12: =AW12 -> 1500 | BF12: =AZ12 -> 1500 | BI12: =BC12 -> 1500 | BL12: =BF12 -> 1500 | BO12: =BI12 -> 1500 | BR12: =BL12 -> 1500 | BU12: =BO12 -> 1500 | BX12: =BR12 -> 1500 | CA12: =BU12 -> 1500 | CD12: =BX12 -> 1500 | CG12: =CA12 -> 1500 | CJ12: =CD12 -> 1500 | CM12: =CG12 -> 1500 | CP12: =CJ12 -> 1500

Sheet экструдер 
C2: экструдер | D2: полотно | E2: нить | F2: назначение | G2: кг | H2: примечание
C3: большой | D3: 56см\76гр\м2 | E3: 2,5 мм-790 Дн | F3: основа | G3: 43380 | H3: сахар
E4: 2,5 мм- 790 Дн | F4: уток | G4: 47718
D5: 85см\60гр\м2 | E5: 3,2 мм - 720 Дн | F5: основа | G5: 5522 | H5: юбка
E6: 2,5 мм - 790 Дн | F6: уток | G6: 7773
D7: 53 см\63 гр\м2 | E7: 2,5 мм-660Дн | F7: основа | G7: 901 | H7: крышка
E8: 2,5 мм- 660 Дн | F8: уток | G8: 968
D9: 56 см\63 гр\м2 | E9: 2,5 мм-680Дн | F9: основа | G9: 20645 | H9: клапан
E10: 2,5 мм- 680 Дн | F10: уток | G10: 22183
C13: итого | G13: =SUM(G3:G12) -> 149090
C14: маленький | D14: 190 см \140 гр\м2 | E14: 2,5 мм - 1500 Дн | F14: основа | G14: 22085
E15: 4,0 мм - 1300 Дн | F15: уток | G15: 22656
D16: 190 см \160 гр\м2 | E16: 2,5 мм - 1700 Дн | F16: основа | G16: 4243
E17: 4,0 мм - 1550 Дн | F17: уток | G17: 4643
D18: 150 см \120 гр\м2 | E18: 2,5 мм - 1350 Дн | F18: основа | G18: 17375
E19: 2,5 мм - 1350 Дн | F19: уток | G19: 17375
D20: 150 см \140 гр\м2 | E20: 2,5 мм - 1550 Дн | F20: основа | G20: 2479
E21: 2,5 мм - 1550 Дн | F21: уток | G21: 2479
D22: 105см \160 гр\м2 | E22: 2,5 мм - 1700 Дн | F22: основа | G22: 5799
E23: 4,0 мм - 1550 Дн | F23: уток | G23: 6345
C24: ИТОГО | G24: =SUM(G14:G23) -> 105479

Sheet план бб
B1: тип | C1: вид | D1: параметры | E1: ширина, м | F1: длина, м | G1: плотность, гр\м2 | H1: длина загтовки, см | I1: вес готового гр | J1: вес заготовки, гр | K1: заказ в шт | L1: метраж, м | M1: метраж отходов и браков (2%) | N1: итого, м | O1: примечание\тоннаж
B2: рпп | C2: фальц | D2: 190\140 | E2: 1.9 | F2: 1.38 | G2: 140 | H2: 1.38 | I2: =E2*F2*G2*2 -> 734.16 | J2: =I2 -> 734.16 | K2: 35000 | L2: =K2*H2 -> 48300 | M2: =L2*2/100 -> 966 | N2: =SUM(L2:M2) -> 49266 | O2: =N2*J2/1000 -> 36169.127
B3: рпп | C3: фальц | D3: 190\140 | E3: 1.9 | F3: 1.58 | G3: 140 | H3: 1.58 | I3: =E3*F3*G3*2 -> 840.56 | J3: =I3 -> 840.56 | K3: 15000 | L3: =K3*H3 -> 23700 | M3: =L3*2/100 -> 474 | N3: =SUM(L3:M3) -> 24174 | O3: =N3*J3/1000 -> 20319.697
B4: рпп | C4: фальц | D4: 190\140 | E4: 1.9 | F4: 1.88 | G4: 140 | H4: 1.88 | I4: =E4*F4*G4*2 -> 1000.16 | J4: =I4 -> 1000.16 | K4: 5000 | L4: =K4*H4 -> 9400 | M4: =L4*2/100 -> 188 | N4: =SUM(L4:M4) -> 9588 | O4: =N4*J4/1000 -> 9589.5341
B5: рпп | C5: фальц | D5: 190\160 | E5: 1.9 | F5: 1.38 | G5: 160 | H5: 1.38 | I5: =E5*F5*G5*2 -> 839.04 | J5: =I5 -> 839.04 | K5: 10000 | L5: =K5*H5 -> 13800 | M5: =L5*2/100 -> 276 | N5: =SUM(L5:M5) -> 14076 | O5: =N5*J5/1000 -> 11810.327
B6: рпп | C6: фальц | D6: 150\120 | E6: 1.5 | F6: 2.24 | G6: 120 | H6: 2.24 | I6: =E6*F6*G6*2 -> 806.4 | J6: =I6 -> 806.4 | K6: 40000 | L6: =K6*H6 -> 89600 | M6: =L6*2/100 -> 1792 | N6: =SUM(L6:M6) -> 91392 | O6: =N6*J6/1000 -> 73698.509
B7: рпп | C7: фальц | D7: 150\140 | E7: 1.5 | F7: 2.24 | G7: 140 | H7: 2.24 | I7: =E7*F7*G7*2 -> 940.8 | J7: =I7 -> 940.8 | K7: 5000 | L7: =K7*H7 -> 11200 | M7: =L7*2/100 -> 224 | N7: =SUM(L7:M7) -> 11424 | O7: =N7*J7/1000 -> 10747.699
B8: рпп | C8: 2хслойное полотно разрез по бокам | D8: 105\160 | E8: 1.05 | F8: 1.05 | G8: 160 | H8: 1.05 | I8: =E8*F8*G8*2 -> 352.8 | J8: =I8 -> 352.8 | K8: 65000 | L8: =(K8*H8)/2 -> 34125 | M8: =L8*2/100 -> 682.5 | N8: =SUM(L8:M8) -> 34807.5 | O8: =N8*J8/1000 -> 12280.086
B9: рпп | I9: =E9*F9*G9*2 -> 0 | J9: =I9 -> 0 | L9: =K9*H9 -> 0 | M9: =L9*2/100 -> 0 | N9: =SUM(L9:M9) -> 0 | O9: =N9*J9/1000 -> 0
B10: ИТОГО | N10: =SUM(N2:N9) -> 234727.5
B11: максимум возможность станков | N11: =10*500*2*30 -> 300000
N12: =N11-N10 -> 65272.5

Sheet план ткацкий просте станки
B1: тип | C1: вид | E1: ширина, м | F1: длина, м | G1: плотность, гр\м2 | H1: длина загтовки, см | I1: вес готового гр | J1: вес заготовки, гр | K1: заказ в шт | L1: метраж, м | M1: метраж отходов и браков (2%) | N1: итого, м | O1: тоннаж | P1: примечание
B2: МП-I | C2: АгВ | D2: сахар | E2: 0.56 | F2: 0.96 | G2: 76 | H2: 103 | I2: 110 | J2: 88 | K2: =1000000 -> 1000000 | L2: =K2*(H2/100) -> 1030000 | M2: =L2*2/100 -> 20600 | N2: =SUM(L2:M2) -> 1050600 | O2: =N2*E2*G2/1000*2 -> 89427.072 | P2: 5 фур сахара | Q2: =0.56*1*2*0.076 -> 0.08512 | R2: =Q2*N2 -> 89427.072
B3: РПП | D3: юбка | E3: 0.85 | F3: 3.8 | G3: 60 | H3: 380 | I3: =0.85*3.8*60 -> 193.8 | J3: =I3 -> 193.8 | K3: ='черновик с расчетами'!R2 -> 32000 | L3: =K3*(H3/100) -> 121600 | M3: =L3*2/100 -> 2432 | N3: =SUM(L3:M3) -> 124032 | O3: =N3*E3*G3/1000*2 -> 12651.264 | P3: 32 тыс бб с юбкой
B4: РПП | D4: Крышка | E4: 0.53 | F4: 1.05 | G4: 63 | H4: 105 | I4: =1.05*1.05*60 -> 66.15 | J4: =I4 -> 66.15 | K4: ='черновик с расчетами'!G10+'черновик с расчетами'!G16+'черновик с расчетами'!G18+'черновик с расчетами'!G20+'черновик с расчетами'!G24 -> 25000 | L4: =K4*(H4/100) -> 26250 | M4: =L4*2/100 -> 525 | N4: =SUM(L4:M4) -> 26775 | O4: =N4*E4*G4/1000*2 -> 1788.0345 | P4: 25000 бб с загрузкой
B5: РПП | D5: Клапан | E5: 0.56 | F5: 0.6 | G5: 63 | H5: 60 | I5: =0.56*0.6*2*60 -> 40.32 | J5: =I5 -> 40.32 | K5: ='черновик с расчетами'!S2 -> 40000 | L5: =K5*(H5/100) -> 24000 | M5: =L5*2/100 -> 480 | N5: =SUM(L5:M5) -> 24480 | O5: =N5*E5*G5/1000*2 -> 1727.3088 | P5: 40000 шт комплектация загр выгр
B6: МП-I | C6: А | D6: мука | E6: 0.56 | F6: 1.05 | G6: 63 | H6: 108 | I6: 79 | J6: 79 | K6: =L6/1.13 -> 482292.69 | L6: =N6-M6 -> 544990.74 | M6: =N6*102/100-N6 -> 11122.26 | N6: =N8-N2-N3-N4-N5 -> 556113 | O6: =N6*E6*G6/1000*2 -> 39239.333 | P6: остальной метраж
B7: ИТОГО | N7: =N2+N3+N5+N6+N4 -> 1782000 | O7: =SUM(O2:O6) -> 144833.01 | P7: загрузка простых станков
B8: максимум возможность станков | N8: =27*1100*2*30 -> 1782000 | O8: =N8*E8*G8/1000*2 -> 0
N9: =N8-N7 -> 0

Sheet расчет мешочное 
B1: Технические характеристики ткани для мешка 56\96 76 гр\2 сахар
A3: № п\п | B3: Наименование по заказу | C3: ? | D3: Номенклатура | E3: Планируемый выпуск в штуках, шт | F3: Вид оборудования для производства ткани | G3: Ширина полотна, см, ±0,5см | H3: Плотность тканое полотно, гр\м², ±3% | I3: Структура плетения полотна
A5: 1 | B5: 56 см \96 см сахар 110 гр | C5: сахарный мешок | D5: МП-I-ArB с лог "EAC" 56*96 (76 гр\м2) | E5: 1351350 | F5: Lohia Corp (Nova 6) (от 30 до 90 см) | G5: 56 | H5: 76 | I5: обычное
A7: № п\п | B7: Наименование по заказу | C7: ? | D7: Номенклатура | E7: Рецептура для производства НПП (нити) | G7: НПП мешочная (Нить) | I7: Разрывная нагрузка основа\уток | K7: План производства нити | M7: ИТОГО нити нужно произвести, кг
E8: ПП , % | F8: Карбонат кальция (мел), % | G8: Основа, ширина - денье,мм-Дн | H8: Уток, ширина - денье,мм-Дн | I8: Коэффициент прочности, гр\Дн | J8: Эластичность (удлинение) 23-33% | K8: Основа, кг | L8: Уток, кг
A9: 2 | B9: НПП 2,5 мм-790Дн | C9: нить | D9: НПП 2,5 мм-790Дн | E9: 90 | F9: 10 | G9: 2,5 мм-790 дн | H9: 2,5 мм-790 дн | I9: 5 | J9: 23-33 | K9: =((448*(0.68/9))*L13)*0.001+(((448*(0.68/9))*L13)*0.001)*5*0.01 -> 20635.049 | L9: =((430*(0.68/9*1.12))*L13)*0.001+(((430*(0.68/9*1.12))*L13)*0.001)*5*0.01 -> 22182.678 | M9: =K9+L9 -> 42817.727 | N9: =53*2*10 -> 1060 | O9: =560*2/2.5 -> 448
A11: 3 | B11: Наименование по заказу | C11: ? | D11: Номенклатура | E11: количество нитей основы на заправку станка | F11: Плотность плетения нити на 10 см | H11: разрывная нагрузка полотно кг/с/Strength KgF | J11: Длина рулона, м | K11: Вес рулона, кг | L11: Планируемый выпуск РПП, м (+5% брак отходы каждого передела)
F12: Основа, шт | G12: Уток, шт | H12: Основа | I12: Уток | J12: Стандарт намотки, ±2% за счет усадки нитей | K12: Стандарт намотки ±3% за счет поверхностной плотности полотна
B13: РПП 56 см \76 гр\м2 | C13: полотно | D13: РПП 56 см \76 гр\м2 | E13: =1120/2.5 -> 448 | F13: 40 | G13: 43 | H13: =(790*(40/2)*5*0.95)/1000 -> 75.05 | I13: =(790*(44/2)*5*0.93)/1000 -> 80.817 | J13: 2500 | K13: =2500*0.076*2*0.56 -> 212.8 | L13: 580593
A15: № п\п | B15: Наименование по заказу | C15: ? | D15: Номенклатура | E15: Рецептура для производства НПП (нити) | G15: Ширина , см, ±0,5см | H15: Длина до спайки, см, ±0,5см | I15: Длина с учетои спайки, см, ±0,5см | J15: Толщина, 20 мкм, ±3% | K15: вес 1 шт вкл, гр | L15: количество шт вкладышей с учетом брака | M15: ИТОГО пэ нужно произвести, кг
E16: ПНД , % | F16: Карбонат кальция (мел), %
A17: 4 | B17: ПЭ 58\105 см 19 мкм | C17: вкладыш | D17: ПЭ 58\105 см 19 мкм | E17: 96 | F17: 4 | G17: 58 | H17: 105 | I17: 106 | J17: 19 | K17: =(G17*I17*2*J17*0.093)/1000 -> 21.727032 | M17: =L17*K17/1000 -> 0

Sheet черновик с расчетами
A1: Группа | B1: общая загрузка, шт | C1: № заказа | D1: Вид продукции | E1: вес 1 шт, кг | F1: ед. изм. | G1: ПЛАН | H1: ФАКТ | I1: %выполнения | J1: Примечание | K1: Комментарии | M1: МКР | N1: ед измерения | O1: открытый верх | P1: дно глухое | Q1: крышка | R1: верх юбка | S1: загр выгр | T1: итого
A2: Мешки | B2: =G2+G4 -> 1504621.1 | C2: 1 | D2: МП-I-ArB с лог "EAC" 56*96 (76 гр\м2) | E2: 0.11 | F2: шт | G2: 1000000 | I2: =H2*100/G2 -> 0 | J2: сахар | M2: 4 ленточные | N2: шт | O2: =G6+G12 -> 8000 | P2: =G6+G8+G10+G12+G14+G16+G18+G20+G22+G24 -> 65000 | Q2: =((G10+G16+G18+G20+G24)*1.05)+((((G10+G16+G18+G20+G24)*1.05)*2)/100) -> 26775 | R2: =G8+G14+G22 -> 32000 | S2: =G10*2+G16+G18*2+G20+G24*2 -> 40000 | T2: =Q2 -> 26775
F3: кг | G3: =G2*E2 -> 110000 | I3: =H3*100/G3 -> 0 | M3: 2х стропные | N3: шт | O3: =G26+G28 -> 45000 | S3: 0
C4: 2 | D4: МП-I-A с лог 56*105 (63 гр\м2) | E4: =0.56*1.08*2*0.063+0.003 -> 0.0792048 | F4: шт | G4: =(27*1100*2*30-(((G2+(G2*2/100))*1.03)+T4)-(((27*1100*2*30-(((G2+(G2*2/100))*1.03)+T4))*2)/100))/1.08 -> 504621.06 | I4: =H4*100/G4 -> 0 | J4: мука | M4: метрраж полотен для юбки, загр выгр | N4: м | R4: =(3.8+(3.8*2/100))*R2+(3+(3*2/100))*R3 -> 124032 | S4: =(0.6+(0.6*2/100))*S2 -> 24480 | T4: =R4+S4+T2 -> 175287
F5: кг | G5: =G4*E4 -> 39968.41 | I5: =H5*100/G5 -> 0 | M5: метраж дно | N5: м | P5: =(1.05+(1.05*2/100))*P2 -> 69615 | T5: =P5 -> 69615
A6: МКР 4 ленточные | B6: =G6+G8+G10+G12+G14+G16+G18+G20+G22+G24 -> 65000 | C6: 3 | D6: МКР 1,3 Л4-1,0 ППР1-Е (95х95х130/140) верх открытый, дно глухое | E6: 1.272 | F6: шт | G6: 5000 | I6: =H6*100/G6 -> 0 | J6: МКР 95х95х130х140 | K6: надо уменьшить до 5000 шт
F7: кг | G7: =G6*E6 -> 6360 | I7: =H7*100/G7 -> 0 | R7: 1.9 | S7: 1.38 | T7: 1.58 | U7: 1.88 | V7: итого с учетом 2% брака
C8: 4 | D8: МКР 1,3 Л4-1,0 ППР1-Е (95х95х130/140) верх юбка, дно глухое | E8: 1.51 | F8: шт | G8: 20000 | I8: =H8*100/G8 -> 0 | J8: МКР 95х95х130х140 | K8: увеличить до 20 тыс | R8: 140 | S8: =(G6+G8+G10+G20)*S7 -> 48300 | T8: =(G12+G14+G16)*T7 -> 23700 | U8: =(G18)*U7 -> 9400 | V8: =((S8+T8+U8)+(((S8+T8+U8)*2)/100)) -> 83028
F9: кг | G9: =G8*E8 -> 30200 | I9: =H9*100/G9 -> 0 | R9: 160 | S9: =(G22+G24)*S7 -> 13800 | V9: =((S9+T9+U9)+(((S9+T9+U9)*2)/100)) -> 14076
C10: 5 | D10: МКР 1,3 Л4-1,0 ППР1-Е (95х95х130/140) верх загр, низ выгр | E10: 1.605 | F10: шт | G10: 5000 | I10: =H10*100/G10 -> 0 | J10: МКР 95х95х130х140 | K10: остаавляем | M10: Нужно дно глух, + верх клапан + 5000 шт | R10: 1.5 | S10: 2.24
F11: кг | G11: =G10*E10 -> 8025 | I11: =H11*100/G11 -> 0 | R11: 120 | S11: =G26*S10 -> 89600 | V11: =((S11+T11+U11)+(((S11+T11+U11)*2)/100)) -> 91392
C12: 6 | D12: МКР 1,3 Л4-1,0 ППР1-Е (95х95х150/140) верх открытый, дно глухое | E12: 1.401 | F12: шт | G12: 3000 | I12: =H12*100/G12 -> 0 | J12: МКР 95х95х150х140 | K12: сделать 3000 шт | R12: 140 | S12: =G28*S10 -> 11200 | V12: =((S12+T12+U12)+(((S12+T12+U12)*2)/100)) -> 11424
F13: кг | G13: =G12*E12 -> 4203 | I13: =H13*100/G13 -> 0 | U13: итого | V13: =SUM(V8:V12) -> 199920
C14: 7 | D14: МКР 1,3 Л4-1,0 ППР1-Е (95х95х150/140) верх юбка, дно глухое | E14: 1.64 | F14: шт | G14: 7000 | I14: =H14*100/G14 -> 0 | J14: МКР 95х95х150х140 | K14: сделать 7000 шт | V14: =V13+T5 -> 269535
F15: кг | G15: =G14*E14 -> 11480 | I15: =H15*100/G15 -> 0 | M15: Нужно дно глух, + верх клапан - 5000 шт
C16: 8 | D16: МКР 1,3 Л4-1,0 ППР1-Е (95х95х150/140) верх загр, дно глухое | E16: 1.661 | F16: шт | G16: 5000 | I16: =H16*100/G16 -> 0 | J16: МКР 95х95х180х140 | K16: УБРАТЬ !!! | V16: =8*500*2*30 -> 240000
F17: кг | G17: =G16*E16 -> 8305 | I17: =H17*100/G17 -> 0 | V17: =2*500*2*30 -> 60000
C18: 9 | D18: МКР 1,3 Л4-1,0 ППР1-Е (95х95х180/140) верх загр, низ выгре | E18: 1.941 | F18: шт | G18: 5000 | I18: =H18*100/G18 -> 0 | J18: МКР 95х95х180х140 | K18: УБРАТЬ !!! | M18: Нужно верх клапан + ДНО КЛАПАН 5000 шт
F19: кг | G19: =G18*E18 -> 9705 | I19: =H19*100/G19 -> 0
C20: 10 | D20: МКР 1,3 Л4-1,0 ППР1-Е (95х95х130/140) верх загр, дно глухое | E20: 1.532 | F20: шт | G20: 5000 | I20: =H20*100/G20 -> 0 | J20: МКР 95х95х130х160 | K20: УБРАТЬ !!! | N20: =1000000+(1000000*2/100) -> 1020000
F21: кг | G21: =G20*E20 -> 7660 | I21: =H21*100/G21 -> 0 | P21: =(G2+(G2*2/100))*1.03 -> 1050600 | Q21: =1236187 -> 1236187
C22: 11 | D22: МКР 1,3 Л4-1,0 ППР1-Е (95х95х130/160) верх юбка, дно глухое | E22: 1.615 | F22: шт | G22: 5000 | I22: =H22*100/G22 -> 0 | J22: МКР 95х95х130х160 | K22: 5000 ШТ ОСТАВЛЯЕМ | P22: =1000000*1.03 -> 1030000 | Q22: =27*1100*2*30 -> 1782000
F23: кг | G23: =G22*E22 -> 8075 | I23: =H23*100/G23 -> 0 | P23: =1030000+(1030000*3/100) -> 1060900 | Q23: =Q22-Q21 -> 545813
C24: 12 | D24: МКР 1,3 Л4-1,0 ППР1-Е (95х95х130/160) верх загр, низ выгр | E24: 1.71 | F24: шт | G24: 5000 | I24: =H24*100/G24 -> 0 | J24: МКР 95х95х130х160 | K24: 5000 ШТ ОСТАВЛЯЕМ | Q24: =Q23/1.08 -> 505382.41
F25: кг | G25: =G24*E24 -> 8550 | I25: =H25*100/G25 -> 0
A26: МКР 2х стропные | B26: =G26+G28 -> 45000 | C26: 13 | D26: МКР 0,9 С2-1,0 ППР1-A (75х75х125/120) верх открытый, дно звезда | E26: =0.776 -> 0.776 | F26: шт | G26: 40000 | I26: =H26*100/G26 -> 0 | J26: МКР 75х75х125х120 | K26: СДЕЛАТЬ 40000
F27: кг | G27: =G26*E26 -> 31040 | I27: =H27*100/G27 -> 0
C28: 14 | D28: МКР 0,9 С2-1,0 ППР1-A (75х75х125/140) верх открытый, дно звезда | E28: 0.899 | F28: шт | G28: 5000 | I28: =H28*100/G28 -> 0 | J28: МКР 75х75х125х140 | K28: СДЕЛАТЬ 5000
F29: кг | G29: =G28*E28 -> 4495 | I29: =H29*100/G29 -> 0

Sheet расчет бб
F1: Технические характеристики ткани для производства ББ
A2: № п\п | B2: Наименование по заказу | C2: Предназначение | D2: Номенклатура | E2: Планируемый выпуск в метрах, м | F2: Вид оборудования для производства ткани | G2: Ширина полотна, см, ±1см | H2: Межфальцевое расстояние,см ±0,5см | I2: Внутренне расстояние между фальцаит не более 1 см | J2: Плотность тканое полотно, гр\м², ±3% | K2: Структура плетения полотна | L2: Рецептура для производства НПП (нити) | O2: НПП мешочная (Нить) | Q2: Разрывная нагрузка основа\уток | S2: План производства нити | U2: ИТОГО нити нужно произвести, кг | V2: количество нитей основы на заправку станка | W2: Плотность плетения нити на 10 см | Y2: разрывная нагрузка полотно кг/с/Strength KgF | AA2: Разрывная нагрузка основа\уток, % | AB2: Длина рулона, м | AC2: Вес рулона, кг | AD2: Планируемый выпуск РПП, м (+5% брак отходы каждого передела) | AE2: Планируемый выпуск РППЛП, кг (+5% брак отходы каждого передела)
L3: ПП 030, % | M3: Карбонат кальция (мел), % | N3: УФ стабилизатор , % | O3: Основа, ширина - денье,мм-Дн | P3: Уток, ширина - денье,мм-Дн | Q3: Коэффициент прочности, гр\Дн | R3: Эластичность (удлинение) 23-33% | S3: Основа, кг | T3: Уток, кг | W3: Основа, шт | X3: Уток, шт | Y3: Основа | Z3: Уток | AB3: Стандарт намотки, ±2% за счет усадки нитей | AC3: Стандарт намотки ±3% за счет поверхностной плотности полотна
A4: 1 | B4: 190 cm / 140 гр\м² | C4: БИГ БЕГ | D4: РППФ 190см\140гр\м² | E4: 500 | F4: Lohia Corp (Nova 82) | G4: 190 | H4: 47.5 | I4: не более 1 см | J4: 140 | K4: обычное | L4: 93 | M4: 5.5 | N4: 2 | O4: 2,5 мм - 1500 Дн | P4: 4,0 мм - 1300 Дн | Q4: 5.5 | R4: 18-22 | S4: =((V4*(1.7/9))*AD4)*0.001+(((V4*(1.7/9))*AD4)*0.001)*5*0.01 -> 5798.9295 | T4: =((480*(1.55/9*2.1))*AD4)*0.001+(((480*(1.55/9*2.1))*AD4)*0.001)*5*0.01 -> 6344.7111 | U4: =S4+T4 -> 12143.641 | V4: =2100/2.5 -> 840 | W4: 40 | X4: 48 | Y4: =(1500*(40/2)*5.5*0.95)/1000 -> 156.75 | Z4: =(1300*(48/2)*5.5*0.93)/1000 -> 159.588 | AA4: 20-30 | AB4: 31800 | AC4: =AB4*0.14*2*1.9 -> 16917.6 | AD4: 34807.5 | AE4: =AD4*AC4/AB4 -> 18517.59
AB6: =31800/53 -> 600
H7: =95+95 -> 190
H8: =95/2 -> 47.5

Sheet раскрой бб
A1: Группа | B1: общая загрузка, шт | C1: № заказа | D1: Вид продукции | E1: вес 1 шт, кг | F1: ед. изм. | G1: ПЛАН | H1: ФАКТ | I1: %выполнения | J1: Примечание
A2: МКР 4 ленточные | B2: =G2+G4+G6+G8+G10+G12+G14+G16+G18+G20 -> 65000 | C2: 1 | D2: МКР 1,3 Л4-1,0 ППР1-Е (95х95х130/140) верх открытый, дно глухое | E2: 1.272 | F2: шт | G2: 5000 | I2: =H2*100/G2 -> 0 | J2: МКР 95х95х130х140
F3: кг | G3: =G2*E2 -> 6360 | I3: =H3*100/G3 -> 0
C4: 2 | D4: МКР 1,3 Л4-1,0 ППР1-Е (95х95х130/140) верх юбка, дно глухое | E4: 1.51 | F4: шт | G4: 20000 | I4: =H4*100/G4 -> 0 | J4: МКР 95х95х130х140
F5: кг | G5: =G4*E4 -> 30200 | I5: =H5*100/G5 -> 0
C6: 3 | D6: МКР 1,3 Л4-1,0 ППР1-Е (95х95х130/140) верх загр, низ выгр | E6: 1.605 | F6: шт | G6: 5000 | I6: =H6*100/G6 -> 0 | J6: МКР 95х95х130х140
F7: кг | G7: =G6*E6 -> 8025 | I7: =H7*100/G7 -> 0
C8: 4 | D8: МКР 1,3 Л4-1,0 ППР1-Е (95х95х150/140) верх открытый, дно глухое | E8: 1.401 | F8: шт | G8: 3000 | I8: =H8*100/G8 -> 0 | J8: МКР 95х95х150х140
F9: кг | G9: =G8*E8 -> 4203 | I9: =H9*100/G9 -> 0
C10: 5 | D10: МКР 1,3 Л4-1,0 ППР1-Е (95х95х150/140) верх юбка, дно глухое | E10: 1.64 | F10: шт | G10: 7000 | I10: =H10*100/G10 -> 0 | J10: МКР 95х95х150х140
F11: кг | G11: =G10*E10 -> 11480 | I11: =H11*100/G11 -> 0
C12: 6 | D12: МКР 1,3 Л4-1,0 ППР1-Е (95х95х150/140) верх загр, дно глухое | E12: 1.661 | F12: шт | G12: 5000 | I12: =H12*100/G12 -> 0 | J12: МКР 95х95х150х140
F13: кг | G13: =G12*E12 -> 8305 | I13: =H13*100/G13 -> 0
C14: 7 | D14: МКР 1,3 Л4-1,0 ППР1-Е (95х95х180/140) верх загр, низ выгр | E14: 1.941 | F14: шт | G14: 5000 | I14: =H14*100/G14 -> 0 | J14: МКР 95х95х180х140
F15: кг | G15: =G14*E14 -> 9705 | I15: =H15*100/G15 -> 0
C16: 8 | D16: МКР 1,3 Л4-1,0 ППР1-Е (95х95х130/140) верх загр, дно глухое | E16: 1.532 | F16: шт | G16: 5000 | I16: =H16*100/G16 -> 0 | J16: МКР 95х95х130х140
F17: кг | G17: =G16*E16 -> 7660 | I17: =H17*100/G17 -> 0
C18: 9 | D18: МКР 1,3 Л4-1,0 ППР1-Е (95х95х130/160) верх юбка, дно глухое | E18: 1.615 | F18: шт | G18: 5000 | I18: =H18*100/G18 -> 0 | J18: МКР 95х95х130х160
F19: кг | G19: =G18*E18 -> 8075 | I19: =H19*100/G19 -> 0
C20: 10 | D20: МКР 1,3 Л4-1,0 ППР1-Е (95х95х130/160) верх загр, низ выгр | E20: 1.71 | F20: шт | G20: 5000 | I20: =H20*100/G20 -> 0 | J20: МКР 95х95х130х160
F21: кг | G21: =G20*E20 -> 8550 | I21: =H21*100/G21 -> 0
A22: МКР 2х стропные | B22: =G22+G24 -> 45000 | C22: 11 | D22: МКР 0,9 С2-1,0 ППР1-A (75х75х125/120) верх открытый, дно звезда | E22: =0.776 -> 0.776 | F22: шт | G22: 40000 | I22: =H22*100/G22 -> 0 | J22: МКР 75х75х125х120
F23: кг | G23: =G22*E22 -> 31040 | I23: =H23*100/G23 -> 0
C24: 12 | D24: МКР 0,9 С2-1,0 ППР1-A (75х75х125/140) верх открытый, дно звезда | E24: 0.899 | F24: шт | G24: 5000 | I24: =H24*100/G24 -> 0 | J24: МКР 75х75х125х140
F25: кг | G25: =G24*E24 -> 4495 | I25: =H25*100/G25 -> 0
A28: № заказа | B28: =D1 -> Вид продукции | C28: Нужное количество комплектов каждого | D28: составляющие кроя | E28: Ширина кроя | F28: длина кроя | G28: количество слоев для расчета | H28: плотность полотна | I28: вес 1 шт, кг | J28: тоннаж, кг | K28: примечание
A29: 1 | B29: =D2 -> МКР 1,3 Л4-1,0 ППР1-Е (95х95х130/140) верх открытый, дно глухое | C29: 5000 | D29: ПФ ПОЛОТНО ППР1-Е (95х95х130/140) | E29: 0.95 | F29: 1.38 | G29: 4 | H29: 0.14 | I29: =E29*F29*G29*H29 -> 0.73416 | J29: =I29*C29 -> 3670.8
C30: 5000 | D30: ПФ ДНО ППР1-Е (95х95х130/140) | E30: 1.05 | F30: 1.05 | G30: 1 | H30: 0.16 | I30: =E30*F30*G30*H30 -> 0.1764 | J30: =I30*C30 -> 882
A31: 2 | B31: =D4 -> МКР 1,3 Л4-1,0 ППР1-Е (95х95х130/140) верх юбка, дно глухое | C31: 20000 | D31: ПФ ПОЛОТНО ППР1-Е (95х95х130/140) | E31: 0.95 | F31: 1.38 | G31: 4 | H31: 0.14 | I31: =E31*F31*G31*H31 -> 0.73416 | J31: =I31*C31 -> 14683.2
C32: 20000 | D32: ПФ ДНО ППР1-Е (95х95х130/140) | E32: 1.05 | F32: 1.05 | G32: 1 | H32: 0.16 | I32: =E32*F32*G32*H32 -> 0.1764 | J32: =I32*C32 -> 3528
C33: 20000 | D33: ПФ ЮБКА ППР1-Е (95х95х130/140) | E33: 0.85 | F33: 3.8 | G33: 1 | H33: 0.06 | I33: =E33*F33*G33*H33 -> 0.1938 | J33: =I33*C33 -> 3876
A34: 3 | B34: =D6 -> МКР 1,3 Л4-1,0 ППР1-Е (95х95х130/140) верх загр, низ выгр | C34: 5000 | D34: ПФ ПОЛОТНО ППР1-Е (95х95х130/140) | E34: 0.95 | F34: 1.4 | G34: 4 | H34: 0.14 | I34: =E34*F34*G34*H34 -> 0.7448 | J34: =I34*C34 -> 3724
C35: 5000 | D35: ПФ ДНО ППР1-Е (95х95х130/140) | E35: 1.05 | F35: 1.05 | G35: 1 | H35: 0.16 | I35: =E35*F35*G35*H35 -> 0.1764 | J35: =I35*C35 -> 882
C36: 10000 | D36: ПФ КЛАПАН ППР1-Е (95х95х130/140) | E36: 0.56 | F36: 0.6 | G36: 2 | H36: 0.63 | I36: =E36*F36*G36*H36 -> 0.42336 | J36: =I36*C36 -> 4233.6
C37: 5000 | D37: ПФ КРЫШКА ППР1-Е (95х95х130/140) | E37: 0.53 | F37: 1.05 | G37: 2 | H37: 0.63 | I37: =E37*F37*G37*H37 -> 0.70119 | J37: =I37*C37 -> 3505.95
A38: 4 | B38: =D8 -> МКР 1,3 Л4-1,0 ППР1-Е (95х95х150/140) верх открытый, дно глухое | C38: 3000 | D38: ПФ ПОЛОТНО ППР1-Е (95х95х150/140) | E38: 0.95 | F38: 1.58 | G38: 4 | H38: 0.14 | I38: =E38*F38*G38*H38 -> 0.84056 | J38: =I38*C38 -> 2521.68
C39: 3000 | D39: ПФ ДНО ППР1-Е (95х95х150/140) | E39: 1.05 | F39: 1.05 | G39: 1 | H39: 0.16 | I39: =E39*F39*G39*H39 -> 0.1764 | J39: =I39*C39 -> 529.2
A40: 5 | B40: =D10 -> МКР 1,3 Л4-1,0 ППР1-Е (95х95х150/140) верх юбка, дно глухое | C40: 7000 | D40: ПФ ПОЛОТНО ППР1-Е (95х95х150/140) | E40: 0.95 | F40: 1.58 | G40: 4 | H40: 0.14 | I40: =E40*F40*G40*H40 -> 0.84056 | J40: =I40*C40 -> 5883.92
C41: 7000 | D41: ПФ ДНО ППР1-Е (95х95х150/140) | E41: 1.05 | F41: 1.05 | G41: 1 | H41: 0.16 | I41: =E41*F41*G41*H41 -> 0.1764 | J41: =I41*C41 -> 1234.8
C42: 7000 | D42: ПФ ЮБКА ППР1-Е (95х95х150/140) | E42: 0.85 | F42: 3.8 | G42: 1 | H42: 0.06 | I42: =E42*F42*G42*H42 -> 0.1938 | J42: =I42*C42 -> 1356.6
...

Sheet тлб лента
A1: Группа | B1: общая загрузка, шт | C1: № заказа | D1: Вид продукции | E1: вес 1 шт, кг | F1: ед. изм. | G1: ПЛАН | H1: ФАКТ | I1: %выполнения | J1: Примечание
A2: МКР 4 ленточные | B2: =G2+G4+G6+G8+G10+G12+G14+G16+G18+G20 -> 65000 | C2: 1 | D2: МКР 1,3 Л4-1,0 ППР1-Е (95х95х130/140) верх открытый, дно глухое | E2: 1.272 | F2: шт | G2: 5000 | I2: =H2*100/G2 -> 0 | J2: МКР 95х95х130х140
F3: кг | G3: =G2*E2 -> 6360 | I3: =H3*100/G3 -> 0
C4: 2 | D4: МКР 1,3 Л4-1,0 ППР1-Е (95х95х130/140) верх юбка, дно глухое | E4: 1.51 | F4: шт | G4: 20000 | I4: =H4*100/G4 -> 0 | J4: МКР 95х95х130х140
F5: кг | G5: =G4*E4 -> 30200 | I5: =H5*100/G5 -> 0
C6: 3 | D6: МКР 1,3 Л4-1,0 ППР1-Е (95х95х130/140) верх загр, низ выгр | E6: 1.605 | F6: шт | G6: 5000 | I6: =H6*100/G6 -> 0 | J6: МКР 95х95х130х140
F7: кг | G7: =G6*E6 -> 8025 | I7: =H7*100/G7 -> 0
C8: 4 | D8: МКР 1,3 Л4-1,0 ППР1-Е (95х95х150/140) верх открытый, дно глухое | E8: 1.401 | F8: шт | G8: 3000 | I8: =H8*100/G8 -> 0 | J8: МКР 95х95х150х140
F9: кг | G9: =G8*E8 -> 4203 | I9: =H9*100/G9 -> 0
C10: 5 | D10: МКР 1,3 Л4-1,0 ППР1-Е (95х95х150/140) верх юбка, дно глухое | E10: 1.64 | F10: шт | G10: 7000 | I10: =H10*100/G10 -> 0 | J10: МКР 95х95х150х140
F11: кг | G11: =G10*E10 -> 11480 | I11: =H11*100/G11 -> 0
C12: 6 | D12: МКР 1,3 Л4-1,0 ППР1-Е (95х95х150/140) верх загр, дно глухое | E12: 1.661 | F12: шт | G12: 5000 | I12: =H12*100/G12 -> 0 | J12: МКР 95х95х150х140
F13: кг | G13: =G12*E12 -> 8305 | I13: =H13*100/G13 -> 0
C14: 7 | D14: МКР 1,3 Л4-1,0 ППР1-Е (95х95х180/140) верх загр, низ выгр | E14: 1.941 | F14: шт | G14: 5000 | I14: =H14*100/G14 -> 0 | J14: МКР 95х95х180х140
F15: кг | G15: =G14*E14 -> 9705 | I15: =H15*100/G15 -> 0
C16: 8 | D16: МКР 1,3 Л4-1,0 ППР1-Е (95х95х130/140) верх загр, дно глухое | E16: 1.532 | F16: шт | G16: 5000 | I16: =H16*100/G16 -> 0 | J16: МКР 95х95х130х140
F17: кг | G17: =G16*E16 -> 7660 | I17: =H17*100/G17 -> 0
C18: 9 | D18: МКР 1,3 Л4-1,0 ППР1-Е (95х95х130/160) верх юбка, дно глухое | E18: 1.615 | F18: шт | G18: 5000 | I18: =H18*100/G18 -> 0 | J18: МКР 95х95х130х160
F19: кг | G19: =G18*E18 -> 8075 | I19: =H19*100/G19 -> 0
C20: 10 | D20: МКР 1,3 Л4-1,0 ППР1-Е (95х95х130/160) верх загр, низ выгр | E20: 1.71 | F20: шт | G20: 5000 | I20: =H20*100/G20 -> 0 | J20: МКР 95х95х130х160
F21: кг | G21: =G20*E20 -> 8550 | I21: =H21*100/G21 -> 0
A22: МКР 2х стропные | B22: =G22+G24 -> 45000 | C22: 11 | D22: МКР 0,9 С2-1,0 ППР1-A (75х75х125/120) верх открытый, дно звезда | E22: =0.776 -> 0.776 | F22: шт | G22: 40000 | I22: =H22*100/G22 -> 0 | J22: МКР 75х75х125х120
F23: кг | G23: =G22*E22 -> 31040 | I23: =H23*100/G23 -> 0
C24: 12 | D24: МКР 0,9 С2-1,0 ППР1-A (75х75х125/140) верх открытый, дно звезда | E24: 0.899 | F24: шт | G24: 5000 | I24: =H24*100/G24 -> 0 | J24: МКР 75х75х125х140
F25: кг | G25: =G24*E24 -> 4495 | I25: =H25*100/G25 -> 0
A28: № заказа | B28: =D1 -> Вид продукции | C28: Нужное количество комплектов каждого | D28: составляющие кроя | E28: Ширина кроя, см | F28: длина кроя, м | G28: количество лент, шт | H28: вес 1 метра ленты, кг | I28: весдля 1 бб , кг | J28: тоннаж, кг | K28: примечание
A29: 1 | B29: =D2 -> МКР 1,3 Л4-1,0 ППР1-Е (95х95х130/140) верх открытый, дно глухое | C29: 5000 | D29: ПФ ТЛБ 4,5см | E29: 4.5 | F29: =0.45+0.9+0.5 -> 1.85 | G29: 4 | H29: =0.03866 -> 0.03866 | I29: =G29*H29*F29 -> 0.286084 | J29: =I29*C29 -> 1430.42
A30: 2 | B30: =D4 -> МКР 1,3 Л4-1,0 ППР1-Е (95х95х130/140) верх юбка, дно глухое | C30: 20000 | D30: ПФ ТЛБ 4,5см | E30: 4.5 | F30: =0.45+0.9+0.5 -> 1.85 | G30: 4 | H30: =0.03866 -> 0.03866 | I30: =G30*H30*F30 -> 0.286084 | J30: =I30*C30 -> 5721.68
C31: 20000 | D31: ПФ ТЛБ 1,5см | E31: 1.5 | F31: 2 | G31: 1 | H31: 0.015 | I31: =G31*H31*F31 -> 0.03 | J31: =I31*C31 -> 600
A32: 3 | B32: =D6 -> МКР 1,3 Л4-1,0 ППР1-Е (95х95х130/140) верх загр, низ выгр | C32: 5000 | D32: ПФ ТЛБ 4,5см | E32: 4.5 | F32: =0.45+0.9+0.5 -> 1.85 | G32: 4 | H32: =0.03866 -> 0.03866 | I32: =G32*H32*F32 -> 0.286084 | J32: =I32*C32 -> 1430.42
C33: 10000 | D33: ПФ ТЛБ 1,5см | E33: 1.5 | F33: 1.5 | G33: 1 | H33: 0.015 | I33: =G33*H33*F33 -> 0.0225 | J33: =I33*C33 -> 225 | L33: =0.015*10000 -> 150
A34: 4 | B34: =D8 -> МКР 1,3 Л4-1,0 ППР1-Е (95х95х150/140) верх открытый, дно глухое | C34: 5000 | D34: ПФ ТЛБ 4,5см | E34: 4.5 | F34: =F35 -> 2 | G34: 4 | H34: =0.03866 -> 0.03866 | I34: =G34*H34*F34 -> 0.30928 | J34: =I34*C34 -> 1546.4
A35: 5 | B35: =D10 -> МКР 1,3 Л4-1,0 ППР1-Е (95х95х150/140) верх юбка, дно глухое | C35: 7000 | D35: ПФ ТЛБ 4,5см | E35: 4.5 | F35: =0.5+1+0.5 -> 2 | G35: 4 | H35: =0.03866 -> 0.03866 | I35: =G35*H35*F35 -> 0.30928 | J35: =I35*C35 -> 2164.96
C36: 7000 | D36: ПФ ТЛБ 1,5см | E36: 1.5 | F36: 2 | G36: 1 | H36: 0.015 | I36: =G36*H36*F36 -> 0.03 | J36: =I36*C36 -> 210
A37: 6 | B37: =D12 -> МКР 1,3 Л4-1,0 ППР1-Е (95х95х150/140) верх загр, дно глухое | C37: 7000 | D37: ПФ ТЛБ 4,5см | E37: 4.5 | F37: =0.5+1+0.5 -> 2 | G37: 4 | H37: =0.03866 -> 0.03866 | I37: =G37*H37*F37 -> 0.30928 | J37: =I37*C37 -> 2164.96
C38: 7000 | D38: ПФ ТЛБ 1,5см | E38: 1.5 | F38: 1.5 | G38: 1 | H38: 0.015 | I38: =G38*H38*F38 -> 0.0225 | J38: =I38*C38 -> 157.5
A39: 7 | B39: =D14 -> МКР 1,3 Л4-1,0 ППР1-Е (95х95х180/140) верх загр, низ выгр | C39: 5000 | D39: ПФ ТЛБ 4,5см | E39: 4.5 | F39: =0.6+1.2+0.5 -> 2.3 | G39: 4 | H39: =0.03866 -> 0.03866 | I39: =G39*H39*F39 -> 0.355672 | J39: =I39*C39 -> 1778.36
C40: 10000 | D40: ПФ ТЛБ 1,5см | E40: 1.5 | F40: 1.5 | G40: 1 | H40: 0.015 | I40: =G40*H40*F40 -> 0.0225 | J40: =I40*C40 -> 225
A41: 8 | B41: =D16 -> МКР 1,3 Л4-1,0 ППР1-Е (95х95х130/140) верх загр, дно глухое | C41: 5000 | D41: ПФ ТЛБ 4,5см | E41: 4.5 | F41: =0.45+0.9+0.5 -> 1.85 | G41: 4 | H41: =0.03866 -> 0.03866 | I41: =G41*H41*F41 -> 0.286084 | J41: =I41*C41 -> 1430.42
C42: 5000 | D42: ПФ ТЛБ 1,5см | E42: 1.5 | F42: 1.5 | G42: 1 | H42: 0.015 | I42: =G42*H42*F42 -> 0.0225 | J42: =I42*C42 -> 112.5
...
